Workbook
Name Categoria: 'Strutture ricettive'!$A$2:$A$1048576
Name Città: 'Strutture ricettive'!$E$2:$E$1048576
Name Denominazione: 'Strutture ricettive'!$B$2:$B$1048576
Name Indirizzo: 'Strutture ricettive'!$D$2:$D$1048576
Name Indirizzo_di_posta_elettronica: 'Strutture ricettive'!$I$2:$I$1048576
Name Indirizzo_internet: 'Strutture ricettive'!$H$2:$H$1048576
Name Localita: 'Strutture ricettive'!$G$2:$G$1048576
Name Nome_Struttura: '[1]Strutture ricettive'!$B$2:$B$1048576

Sheet Strutture ricettive
A1: Categoria | B1: Denominazione | C1: Annulla spazi | D1: Indirizzo | E1: Città | F1: Chiave | G1: Localita | H1: Indirizzo internet | I1: Indirizzo di posta elettronica
A2: ALLOGGI IN AFFITTO | B2: 124 AFFITTACAMERE | C2: =TRIM(B2) -> 124 AFFITTACAMERE | D2: via Sandro Pertini 55 | E2: TOLENTINO | F2: =C2&"_"&E2&"_"&D2 -> 124 AFFITTACAMERE_TOLENTINO_via Sandro Pertini 55 | I2: info@124tolentino.it.
A3: ALLOGGI IN AFFITTO | B3: 2000 di DIAMANTINI ASSUNTA | C3: =TRIM(B3) -> 2000 di DIAMANTINI ASSUNTA | D3: via giacomo puccini 9 | E3: SASSOCORVARO | F3: =C3&"_"&E3&"_"&D3 -> 2000 di DIAMANTINI ASSUNTA_SASSOCORVARO_via giacomo puccini 9 | G3: SASSOCORVARO | I3: fabbrica-delle-idee@libero.it
A4: ALLOGGI IN AFFITTO | B4: 3 JOLIE | C4: =TRIM(B4) -> 3 JOLIE | D4: viale Caduti del Lavoro 1 | E4: SIROLO | F4: =C4&"_"&E4&"_"&D4 -> 3 JOLIE_SIROLO_viale Caduti del Lavoro 1 | G4: SIROLO | H4: www.cameresirolo.com | I4: info@cameresirolo.com
A5: STABILIMENTI BALNEARI | B5: 30 NODI | C5: =TRIM(B5) -> 30 NODI | D5: via del golfo 25 | E5: NUMANA | F5: =C5&"_"&E5&"_"&D5 -> 30 NODI_NUMANA_via del golfo 25 | G5: NUMANA | I5: alexpanocchi@hotmail.com
A6: BED & BREAKFAST | B6: 4 PINI | C6: =TRIM(B6) -> 4 PINI | D6: Via della Madonnetta 10/A | E6: ANCONA | F6: =C6&"_"&E6&"_"&D6 -> 4 PINI_ANCONA_Via della Madonnetta 10/A | G6: ANCONA | H6: http://www.4pini.it | I6: info@4pini.it
A7: STABILIMENTI BALNEARI | B7: 4 SORELLE | C7: =TRIM(B7) -> 4 SORELLE | D7: viale alcide de gasperi 1 1 | E7: GROTTAMMARE | F7: =C7&"_"&E7&"_"&D7 -> 4 SORELLE_GROTTAMMARE_viale alcide de gasperi 1 1
A8: CAMPEGGI | B8: 4 STAGIONI | C8: =TRIM(B8) -> 4 STAGIONI | D8: contrada Brilli 1 | E8: SARNANO | F8: =C8&"_"&E8&"_"&D8 -> 4 STAGIONI_SARNANO_contrada Brilli 1 | G8: SARNANO | H8: www.camping4stagioni.it | I8: quattrostagioni@camping.it
A9: STABILIMENTI BALNEARI | B9: 45.COM | C9: =TRIM(B9) -> 45.COM | E9: SAN BENEDETTO DEL TRONTO | F9: =C9&"_"&E9&"_"&D9 -> 45.COM_SAN BENEDETTO DEL TRONTO_
A10: ALTRI ALLOGGI PRIVATI | B10: 5 ALBERI | C10: =TRIM(B10) -> 5 ALBERI | D10: via Gualdo 7 | E10: BELVEDERE OSTRENSE | F10: =C10&"_"&E10&"_"&D10 -> 5 ALBERI_BELVEDERE OSTRENSE_via Gualdo 7 | H10: www.5alberi.com | I10: info@5alberi.com
A11: BED & BREAKFAST | B11: 5 COLLI | C11: =TRIM(B11) -> 5 COLLI | D11: COLLE SANT'ANGELO 32A | E11: MONTEPRANDONE | F11: =C11&"_"&E11&"_"&D11 -> 5 COLLI_MONTEPRANDONE_COLLE SANT'ANGELO 32A | H11: cinquecolli.bnb@hotmail.com | I11: bruni.cinzia@hotmail.it
A12: TURISMO RURALE | B12: 9 CAMERE | C12: =TRIM(B12) -> 9 CAMERE | D12: via Cave 5 | E12: SIROLO | F12: =C12&"_"&E12&"_"&D12 -> 9 CAMERE_SIROLO_via Cave 5 | H12: www.novecamere.it | I12: info@novecamere.it
A13: ALLOGGI AGRITURISTICI | B13: A 3 PASSI | C13: =TRIM(B13) -> A 3 PASSI | D13: via del Carmine 51 | E13: ANCONA | F13: =C13&"_"&E13&"_"&D13 -> A 3 PASSI_ANCONA_via del Carmine 51 | H13: www.a3passi.com | I13: a3passi@aziendadelcarmine.it
A14: ALLOGGI AGRITURISTICI | B14: A CASA DA ANGELO | C14: =TRIM(B14) -> A CASA DA ANGELO | D14: contrada San Giacomo 26 | E14: GROTTAMMARE | F14: =C14&"_"&E14&"_"&D14 -> A CASA DA ANGELO_GROTTAMMARE_contrada San Giacomo 26 | G14: GROTTAMMARE | I14: agriturismoacasadaangelo@alice.it
A15: BED & BREAKFAST | B15: A CASA DI NONNA DI CROIA MAURO | C15: =TRIM(B15) -> A CASA DI NONNA DI CROIA MAURO | D15: VIA ABRUZZO 7 | E15: LORETO | F15: =C15&"_"&E15&"_"&D15 -> A CASA DI NONNA DI CROIA MAURO_LORETO_VIA ABRUZZO 7 | G15: LORETO | I15: maurocroia@alice.it
A16: BED & BREAKFAST | B16: A CASA DI NONNA LINDA | C16: =TRIM(B16) -> A CASA DI NONNA LINDA | D16: Via Gherardi 54 | E16: SENIGALLIA | F16: =C16&"_"&E16&"_"&D16 -> A CASA DI NONNA LINDA_SENIGALLIA_Via Gherardi 54 | G16: SENIGALLIA | I16: info@acasadinonnalinda.it
A17: BED & BREAKFAST | B17: A CASA DI PAOLA | C17: =TRIM(B17) -> A CASA DI PAOLA | D17: viale Giovanni XXIII 6 | E17: JESI | F17: =C17&"_"&E17&"_"&D17 -> A CASA DI PAOLA_JESI_viale Giovanni XXIII 6 | H17: www.casapaola.it | I17: info@casapaola.it
A18: BED & BREAKFAST | B18: A CASA DI PETER | C18: =TRIM(B18) -> A CASA DI PETER | D18: VIA O.MARCHETTI 24 | E18: CIVITANOVA MARCHE | F18: =C18&"_"&E18&"_"&D18 -> A CASA DI PETER_CIVITANOVA MARCHE_VIA O.MARCHETTI 24 | G18: CIVITANOVA MARCHE | I18: pietro.forani@virgilio.it
A19: BED & BREAKFAST | B19: A CASA DI ROMOLO | C19: =TRIM(B19) -> A CASA DI ROMOLO | D19: via Ramazzani 144 | E19: ARCEVIA | F19: =C19&"_"&E19&"_"&D19 -> A CASA DI ROMOLO_ARCEVIA_via Ramazzani 144 | G19: ARCEVIA | I19: acasadiromolo@gmail.com
A20: BED & BREAKFAST | B20: A DUE PASSI DAL CIELO | C20: =TRIM(B20) -> A DUE PASSI DAL CIELO | D20: VIALE DELLA VITTORIA 72 | E20: JESI | F20: =C20&"_"&E20&"_"&D20 -> A DUE PASSI DAL CIELO_JESI_VIALE DELLA VITTORIA 72 | G20: JESI | I20: aduepassidalcielo@tim.it
A21: STABILIMENTI BALNEARI | B21: ABBADETTA MARE | C21: =TRIM(B21) -> ABBADETTA MARE | D21: lungomare marconi 5 5 | E21: SAN BENEDETTO DEL TRONTO | F21: =C21&"_"&E21&"_"&D21 -> ABBADETTA MARE_SAN BENEDETTO DEL TRONTO_lungomare marconi 5 5 | G21: SENIGALLIA | H21: info@lapacehotel.it | I21: www.lapacehotel.it
A22: ALBERGHI | B22: ABBADETTA RESORT | C22: =TRIM(B22) -> ABBADETTA RESORT | D22: via Abbadetta 36 | E22: ACQUAVIVA PICENA | F22: =C22&"_"&E22&"_"&D22 -> ABBADETTA RESORT_ACQUAVIVA PICENA_via Abbadetta 36 | G22: ACQUAVIVA PICENA | H22: www.abbadetta.it | I22: sabrina-riccioni@hotmail.com
A23: CASE PER FERIE | B23: ABBADIA DI ELCITO | C23: =TRIM(B23) -> ABBADIA DI ELCITO | D23: localita' Elcito 1 | E23: SAN SEVERINO MARCHE | F23: =C23&"_"&E23&"_"&D23 -> ABBADIA DI ELCITO_SAN SEVERINO MARCHE_localita' Elcito 1 | G23: SAN SEVERINO MARCHE | I23: edo11@libero.it
A24: ALBERGHI | B24: ABBAZIA CLUB HOTEL | C24: =TRIM(B24) -> ABBAZIA CLUB HOTEL | D24: viale Cristoforo Colombo 107 | E24: MONDOLFO | F24: =C24&"_"&E24&"_"&D24 -> ABBAZIA CLUB HOTEL_MONDOLFO_viale Cristoforo Colombo 107 | G24: MONDOLFO | H24: www.clubhotel-marotta.com | I24: info@clubhotel-marotta.com
A25: OSTELLI PER LA GIOVENTU' | B25: ABBAZIA DI SAN BIAGIO IL CAPRILE | C25: =TRIM(B25) -> ABBAZIA DI SAN BIAGIO IL CAPRILE | D25: frazione Campodonico 91/b | E25: FABRIANO | F25: =C25&"_"&E25&"_"&D25 -> ABBAZIA DI SAN BIAGIO IL CAPRILE_FABRIANO_frazione Campodonico 91/b | G25: FABRIANO | H25: www.sanbiagioincaprile.it | I25: hostellosanbiagio@libero.it
A26: STABILIMENTI BALNEARI | B26: ABBRONZATISSIMA | C26: =TRIM(B26) -> ABBRONZATISSIMA | D26: via cristoforo colombo 1 1 | E26: FALCONARA MARITTIMA | F26: =C26&"_"&E26&"_"&D26 -> ABBRONZATISSIMA_FALCONARA MARITTIMA_via cristoforo colombo 1 1 | G26: FALCONARA MARITTIMA
A27: ALLOGGI IN AFFITTO | B27: ABRAMO | C27: =TRIM(B27) -> ABRAMO | D27: via annibal caro 80 | E27: PORTO RECANATI | F27: =C27&"_"&E27&"_"&D27 -> ABRAMO_PORTO RECANATI_via annibal caro 80 | G27: PORTO RECANATI | H27: www.abramocamere.it | I27: info@abramocamere.it
A28: TURISMO RURALE | B28: ACANTO COUNTRY HOUSE | C28: =TRIM(B28) -> ACANTO COUNTRY HOUSE | D28: via Ancarano 18 | E28: SIROLO | F28: =C28&"_"&E28&"_"&D28 -> ACANTO COUNTRY HOUSE_SIROLO_via Ancarano 18 | G28: SIROLO | H28: www.acantocountryhouse.com | I28: info@acantocountryhouse.com
A29: STABILIMENTI BALNEARI | B29: ACAPULCO | C29: =TRIM(B29) -> ACAPULCO | E29: PORTO RECANATI | F29: =C29&"_"&E29&"_"&D29 -> ACAPULCO_PORTO RECANATI_ | G29: PORTO RECANATI
A30: ALLOGGI AGRITURISTICI | B30: ACCIPICCHIA | C30: =TRIM(B30) -> ACCIPICCHIA | D30: contrada campana 146 | E30: ANCONA | F30: =C30&"_"&E30&"_"&D30 -> ACCIPICCHIA_ANCONA_contrada campana 146 | G30: collina di PORTONOVO | H30: www.cantinapolenta.it | I30: info@cantinapolenta.it
A31: ALLOGGI IN AFFITTO | B31: ACCOMODATION CASA CAVOUR | C31: =TRIM(B31) -> ACCOMODATION CASA CAVOUR | D31: G.MORETTI 1 | E31: SAN BENEDETTO DEL TRONTO | F31: =C31&"_"&E31&"_"&D31 -> ACCOMODATION CASA CAVOUR_SAN BENEDETTO DEL TRONTO_G.MORETTI 1 | H31: www.casacavoursanbenedetto.it | I31: info@casacavoursanbenedetto.it
A32: ALTRI ALLOGGI PRIVATI | B32: ACERO FRANCESCO E FILIPPO | C32: =TRIM(B32) -> ACERO FRANCESCO E FILIPPO | D32: via Monte Polo 10 | E32: URBINO | F32: =C32&"_"&E32&"_"&D32 -> ACERO FRANCESCO E FILIPPO_URBINO_via Monte Polo 10 | I32: m.g.acero@alice.it
A33: ALTRI ALLOGGI PRIVATI | B33: ACERO MARIA GRAZIA | C33: =TRIM(B33) -> ACERO MARIA GRAZIA | D33: via Monte Polo 8 | E33: URBINO | F33: =C33&"_"&E33&"_"&D33 -> ACERO MARIA GRAZIA_URBINO_via Monte Polo 8 | I33: m.g.acero@alice.it
A34: ALLOGGI AGRITURISTICI | B34: ACQUABATTIGLIA | C34: =TRIM(B34) -> ACQUABATTIGLIA | D34: via fossato 5 | E34: CANTIANO | F34: =C34&"_"&E34&"_"&D34 -> ACQUABATTIGLIA_CANTIANO_via fossato 5 | G34: ACQUABATTAGLIA | H34: www.acquabattaglia.com | I34: picorri@gmail.com
A35: ALLOGGI IN AFFITTO | B35: ACQUAMARINA | C35: =TRIM(B35) -> ACQUAMARINA | D35: via C. Maffei 68 | E35: SAN BENEDETTO DEL TRONTO | F35: =C35&"_"&E35&"_"&D35 -> ACQUAMARINA_SAN BENEDETTO DEL TRONTO_via C. Maffei 68 | H35: www.residenceacquamarina.com | I35: info@appartamentiacquamarina.it
A36: TURISMO RURALE | B36: ACQUANERA | C36: =TRIM(B36) -> ACQUANERA | D36: localita' acquanera 1 | E36: PIOBBICO | F36: =C36&"_"&E36&"_"&D36 -> ACQUANERA_PIOBBICO_localita' acquanera 1 | G36: PIOBBICO | H36: www.acquanera.com | I36: info@acquanera.com
A37: ALBERGHI | B37: ACQUAPARCO VERDE AZZURRO | C37: =TRIM(B37) -> ACQUAPARCO VERDE AZZURRO | D37: localita' San Faustino 6 | E37: CINGOLI | F37: =C37&"_"&E37&"_"&D37 -> ACQUAPARCO VERDE AZZURRO_CINGOLI_localita' San Faustino 6 | G37: CINGOLI | H37: www.verdeazzurro.it | I37: info@verdeazzurro.it
A38: ALLOGGI IN AFFITTO | B38: ACQUAPAZZA ROOM | C38: =TRIM(B38) -> ACQUAPAZZA ROOM | D38: via San Martino 58 | E38: SAN BENEDETTO DEL TRONTO | F38: =C38&"_"&E38&"_"&D38 -> ACQUAPAZZA ROOM_SAN BENEDETTO DEL TRONTO_via San Martino 58 | I38: info@acquapazzaristorante.it
A39: STABILIMENTI BALNEARI | B39: ACQUARIUS | C39: =TRIM(B39) -> ACQUARIUS | D39: viale alcide de gasperi 1 1 | E39: GROTTAMMARE | F39: =C39&"_"&E39&"_"&D39 -> ACQUARIUS_GROTTAMMARE_viale alcide de gasperi 1 1 | G39: GROTTAMMARE
A40: ALLOGGI AGRITURISTICI | B40: ACQUASALATA | C40: =TRIM(B40) -> ACQUASALATA | D40: fraz. Montale 116 | E40: ARCEVIA | F40: =C40&"_"&E40&"_"&D40 -> ACQUASALATA_ARCEVIA_fraz. Montale 116 | G40: MONTALE | H40: www.agriturismoacquasalata.it | I40: a.acquasalata@libero.it
...

Sheet RICERCA
B1: RICERCA STRUTTURA
B3: NOME STRUTTURA | C3: 124 AFFITTACAMERE_TOLENTINO_via Sandro Pertini 55 | D3: ho inserito la chiave perché ci sono diverse strutture con lo stesso nome in città diverse
B4: CITTA' | C4: =_xlfn.XLOOKUP(C3,'Strutture ricettive'!F:F,'Strutture ricettive'!E:E) -> TOLENTINO
B5: INDIRIZZO | C5: =IF(_xlfn.XLOOKUP($C$3,'Strutture ricettive'!F:F,'Strutture ricettive'!D:D)="","Non disponibile",_xlfn.XLOOKUP($C$3,'Strutture ricettive'!F:F,'Strutture ricettive'!D:D)) -> via Sandro Pertini 55
B6: EMAIL | C6: =IF(_xlfn.XLOOKUP($C$3,'Strutture ricettive'!F:F,'Strutture ricettive'!I:I)="","Non disponibile",_xlfn.XLOOKUP($C$3,'Strutture ricettive'!F:F,'Strutture ricettive'!I:I)) -> info@124tolentino.it.
B7: INDIRIZZO WEB | C7: =IF(_xlfn.XLOOKUP($C$3,'Strutture ricettive'!F:F,'Strutture ricettive'!H:H)="","Non disponibile",_xlfn.XLOOKUP($C$3,'Strutture ricettive'!F:F,'Strutture ricettive'!H:H)) -> Non disponibile
B8: Numero totale strutture | C8: =COUNTA('Strutture ricettive'!B:B) -> 6253
B9: Numero strutture per LOCALITA' | C9: =COUNTIF('Strutture ricettive'!E:E,C4) -> 37

Sheet PIVOT
A1: Città | B1: (Tutto)
A3: Categoria | B3: Numero strutture
A4: ALBERGHI | B4: 814
A5: ALLOGGI AGRITURISTICI | B5: 829
A6: ALLOGGI IN AFFITTO | B6: 540
A7: ALTRI ALLOGGI PRIVATI | B7: 719
A8: ALTRI ESERCIZI RICETTIVI | B8: 13
A9: AREE DI SOSTA (PLEIN AIR) | B9: 86
A10: BED & BREAKFAST | B10: 1808
A11: CAMPEGGI | B11: 93
A12: CASE PER FERIE | B12: 82
A13: OSTELLI PER LA GIOVENTU' | B13: 30
A14: RESIDENZE TURISTICO ALBERGHIERE | B14: 52
A15: RIFUGI | B15: 16
... A18: VILLAGGI TURISTICI | B18: 17
A19: (vuoto)
A20: Totale complessivo | B20: 6252
